{"rest_depth_snapshot":{"lastUpdateId":1000,"E":1700000000000,"T":1699999999995,"bids":[["49999.9","1.000"],["49999.8","1.150"],["49999.7","1.300"],["49999.6","1.450"],["49999.5","1.600"],["49999.4","1.750"],["49999.3","1.900"],["49999.2","1.000"],["49999.1","1.150"],["49999.0","1.300"],["49998.9","1.450"],["49998.8","1.600"],["49998.7","1.750"],["49998.6","1.900"],["49998.5","1.000"],["49998.4","1.150"],["49998.3","1.300"],["49998.2","1.450"],["49998.1","1.600"],["49998.0","1.750"]],"asks":[["50000.1","0.800"],["50000.2","0.920"],["50000.3","1.040"],["50000.4","1.160"],["50000.5","1.280"],["50000.6","0.800"],["50000.7","0.920"],["50000.8","1.040"],["50000.9","1.160"],["50001.0","1.280"],["50001.1","0.800"],["50001.2","0.920"],["50001.3","1.040"],["50001.4","1.160"],["50001.5","1.280"],["50001.6","0.800"],["50001.7","0.920"],["50001.8","1.040"],["50001.9","1.160"],["50002.0","1.280"]]}}
{"stream":"btcusdt@depth","data":{"e":"depthUpdate","E":1700000000050,"T":1700000000045,"s":"BTCUSDT","U":990,"u":998,"pu":985,"b":[["49999.9","9.999"]],"a":[["50000.1","9.999"]]}}
{"stream":"btcusdt@depth","data":{"e":"depthUpdate","E":1700000000100,"T":1700000000095,"s":"BTCUSDT","U":995,"u":1005,"pu":990,"b":[["49999.9","1.100"]],"a":[["50000.1","0.900"]]}}
{"stream":"btcusdt@depth","data":{"e":"depthUpdate","E":1700000000150,"T":1700000000145,"s":"BTCUSDT","U":1006,"u":1008,"pu":1005,"b":[["49999.8","1.200"],["49998.7","2.000"]],"a":[["50000.2","0.900"],["50001.3","1.700"]]}}
{"stream":"btcusdt@aggTrade","data":{"e":"aggTrade","E":1700000000200,"s":"BTCUSDT","a":9000001,"p":"50000.1","q":"0.010","f":18000002,"l":18000003,"T":1700000000180,"m":false}}
{"stream":"btcusdt@depth","data":{"e":"depthUpdate","E":1700000000250,"T":1700000000245,"s":"BTCUSDT","U":1009,"u":1011,"pu":1008,"b":[["49999.7","1.250"]],"a":[["50000.3","0.940"]]}}
{"stream":"btcusdt@depth","data":{"e":"depthUpdate","E":1700000000300,"T":1700000000295,"s":"BTCUSDT","U":1012,"u":1014,"pu":1011,"b":[["49999.6","1.300"]],"a":[["50000.4","0.980"]]}}
{"stream":"btcusdt@aggTrade","data":{"e":"aggTrade","E":1700000000350,"s":"BTCUSDT","a":9000002,"p":"49999.9","q":"0.012","f":18000004,"l":18000005,"T":1700000000330,"m":true}}
{"stream":"btcusdt@depth","data":{"e":"depthUpdate","E":1700000000400,"T":1700000000395,"s":"BTCUSDT","U":1015,"u":1017,"pu":1014,"b":[["49999.5","1.350"]],"a":[["50000.5","1.020"]]}}
{"stream":"btcusdt@depth","data":{"e":"depthUpdate","E":1700000000450,"T":1700000000445,"s":"BTCUSDT","U":1018,"u":1020,"pu":1017,"b":[["49997.7","3.333"],["49998.7","2.120"]],"a":[["50000.6","1.060"],["50001.3","1.780"]]}}
{"stream":"btcusdt@aggTrade","data":{"e":"aggTrade","E":1700000000500,"s":"BTCUSDT","a":9000003,"p":"50000.1","q":"0.014","f":18000006,"l":18000007,"T":1700000000480,"m":false}}
{"stream":"btcusdt@depth","data":{"e":"depthUpdate","E":1700000000550,"T":1700000000545,"s":"BTCUSDT","U":1021,"u":1023,"pu":1020,"b":[["49999.3","1.450"]],"a":[["50000.7","1.100"]]}}
{"stream":"btcusdt@depth","data":{"e":"depthUpdate","E":1700000000600,"T":1700000000595,"s":"BTCUSDT","U":1024,"u":1026,"pu":1023,"b":[["49999.8","1.500"]],"a":[["50000.2","1.140"]]}}
{"stream":"btcusdt@aggTrade","data":{"e":"aggTrade","E":1700000000650,"s":"BTCUSDT","a":9000004,"p":"49999.9","q":"0.016","f":18000008,"l":18000009,"T":1700000000630,"m":true}}
{"stream":"btcusdt@depth","data":{"e":"depthUpdate","E":1700000000700,"T":1700000000695,"s":"BTCUSDT","U":1027,"u":1029,"pu":1026,"b":[["49999.7","1.550"]],"a":[["50000.3","1.180"]]}}
{"stream":"btcusdt@depth","data":{"e":"depthUpdate","E":1700000000750,"T":1700000000745,"s":"BTCUSDT","U":1030,"u":1032,"pu":1029,"b":[["49999.6","1.600"],["49998.7","2.240"]],"a":[["50000.4","1.220"],["50001.3","1.860"]]}}
{"stream":"btcusdt@aggTrade","data":{"e":"aggTrade","E":1700000000800,"s":"BTCUSDT","a":9000005,"p":"50000.1","q":"0.018","f":18000010,"l":18000011,"T":1700000000780,"m":false}}
{"stream":"btcusdt@depth","data":{"e":"depthUpdate","E":1700000000850,"T":1700000000845,"s":"BTCUSDT","U":1033,"u":1035,"pu":1032,"b":[["49999.5","1.650"]],"a":[["50001.9","0.000"]]}}
{"stream":"btcusdt@depth","data":{"e":"depthUpdate","E":1700000000900,"T":1700000000895,"s":"BTCUSDT","U":1036,"u":1038,"pu":1035,"b":[["49999.4","1.700"]],"a":[["50000.6","1.300"]]}}
{"stream":"btcusdt@aggTrade","data":{"e":"aggTrade","E":1700000000950,"s":"BTCUSDT","a":9000006,"p":"49999.9","q":"0.020","f":18000012,"l":18000013,"T":1700000000930,"m":true}}
{"stream":"btcusdt@depth","data":{"e":"depthUpdate","E":1700000001000,"T":1700000000995,"s":"BTCUSDT","U":1039,"u":1041,"pu":1038,"b":[["49999.3","1.750"]],"a":[["50000.7","1.340"]]}}
{"stream":"btcusdt@depth","data":{"e":"depthUpdate","E":1700000001050,"T":1700000001045,"s":"BTCUSDT","U":1042,"u":1044,"pu":1041,"b":[["49999.8","1.800"],["49998.7","2.360"]],"a":[["50000.2","1.380"],["50001.3","1.940"]]}}
{"stream":"btcusdt@aggTrade","data":{"e":"aggTrade","E":1700000001100,"s":"BTCUSDT","a":9000007,"p":"50000.1","q":"0.022","f":18000014,"l":18000015,"T":1700000001080,"m":false}}
{"stream":"btcusdt@depth","data":{"e":"depthUpdate","E":1700000001150,"T":1700000001145,"s":"BTCUSDT","U":1045,"u":1047,"pu":1044,"b":[["49999.7","1.850"]],"a":[["50000.3","1.420"]]}}
{"stream":"btcusdt@depth","data":{"e":"depthUpdate","E":1700000001200,"T":1700000001195,"s":"BTCUSDT","U":1048,"u":1050,"pu":1047,"b":[["49999.6","1.900"]],"a":[["50000.4","1.460"]]}}
{"stream":"btcusdt@aggTrade","data":{"e":"aggTrade","E":1700000001250,"s":"BTCUSDT","a":9000008,"p":"49999.9","q":"0.024","f":18000016,"l":18000017,"T":1700000001230,"m":true}}
{"stream":"btcusdt@bookTicker","data":{"e":"bookTicker","u":500017,"E":1700000001300,"T":1700000001297,"s":"BTCUSDT","b":"49999.9","B":"1.640","a":"50000.1","A":"1.200"}}
{"stream":"btcusdt@depth","data":{"e":"depthUpdate","E":1700000001350,"T":1700000001345,"s":"BTCUSDT","U":1051,"u":1053,"pu":1050,"b":[["49999.5","1.950"]],"a":[["50000.5","1.500"]]}}
{"stream":"btcusdt@depth","data":{"e":"depthUpdate","E":1700000001400,"T":1700000001395,"s":"BTCUSDT","U":1054,"u":1056,"pu":1053,"b":[["49997.7","5.555"],["49998.7","2.480"]],"a":[["50000.6","1.540"],["50001.3","2.020"]]}}
{"stream":"btcusdt@aggTrade","data":{"e":"aggTrade","E":1700000001450,"s":"BTCUSDT","a":9000009,"p":"50000.1","q":"0.026","f":18000018,"l":18000019,"T":1700000001430,"m":false}}
{"stream":"btcusdt@depth","data":{"e":"depthUpdate","E":1700000001500,"T":1700000001495,"s":"BTCUSDT","U":1057,"u":1059,"pu":1056,"b":[["49999.3","2.050"]],"a":[["50000.7","1.580"]]}}
{"stream":"btcusdt@depth","data":{"e":"depthUpdate","E":1700000001550,"T":1700000001545,"s":"BTCUSDT","U":1060,"u":1062,"pu":1059,"b":[["49999.8","2.100"]],"a":[["50000.2","1.620"]]}}
{"stream":"btcusdt@aggTrade","data":{"e":"aggTrade","E":1700000001600,"s":"BTCUSDT","a":9000010,"p":"49999.9","q":"0.028","f":18000020,"l":18000021,"T":1700000001580,"m":true}}
{"stream":"btcusdt@depth","data":{"e":"depthUpdate","E":1700000001650,"T":1700000001645,"s":"BTCUSDT","U":1063,"u":1065,"pu":1062,"b":[["49999.7","2.150"]],"a":[["50000.3","1.660"]]}}
{"stream":"btcusdt@depth","data":{"e":"depthUpdate","E":1700000001700,"T":1700000001695,"s":"BTCUSDT","U":1066,"u":1068,"pu":1065,"b":[["49999.6","2.200"],["49998.7","2.600"]],"a":[["50000.4","1.700"],["50001.3","2.100"]]}}
{"stream":"btcusdt@aggTrade","data":{"e":"aggTrade","E":1700000001750,"s":"BTCUSDT","a":9000011,"p":"50000.1","q":"0.030","f":18000022,"l":18000023,"T":1700000001730,"m":false}}
{"stream":"btcusdt@depth","data":{"e":"depthUpdate","E":1700000001800,"T":1700000001795,"s":"BTCUSDT","U":1069,"u":1071,"pu":1068,"b":[["49999.5","2.250"]],"a":[["50000.5","1.740"]]}}
{"stream":"btcusdt@depth","data":{"e":"depthUpdate","E":1700000001850,"T":1700000001845,"s":"BTCUSDT","U":1072,"u":1074,"pu":1071,"b":[["49999.4","2.300"]],"a":[["50000.6","1.780"]]}}
{"stream":"btcusdt@aggTrade","data":{"e":"aggTrade","E":1700000001900,"s":"BTCUSDT","a":9000012,"p":"49999.9","q":"0.032","f":18000024,"l":18000025,"T":1700000001880,"m":true}}
{"stream":"btcusdt@depth","data":{"e":"depthUpdate","E":1700000001950,"T":1700000001945,"s":"BTCUSDT","U":1075,"u":1077,"pu":1074,"b":[["49999.3","2.350"]],"a":[["50000.7","1.820"]]}}
{"stream":"btcusdt@depth","data":{"e":"depthUpdate","E":1700000002000,"T":1700000001995,"s":"BTCUSDT","U":1078,"u":1080,"pu":1077,"b":[["49999.8","2.400"],["49998.7","2.720"]],"a":[["50000.2","1.860"],["50001.3","2.180"]]}}
{"stream":"btcusdt@aggTrade","data":{"e":"aggTrade","E":1700000002050,"s":"BTCUSDT","a":9000013,"p":"50000.1","q":"0.034","f":18000026,"l":18000027,"T":1700000002030,"m":false}}
{"stream":"btcusdt@depth","data":{"e":"depthUpdate","E":1700000002100,"T":1700000002095,"s":"BTCUSDT","U":1081,"u":1083,"pu":1080,"b":[["49999.7","2.450"]],"a":[["50000.3","1.900"]]}}
{"stream":"btcusdt@depth","data":{"e":"depthUpdate","E":1700000002150,"T":1700000002145,"s":"BTCUSDT","U":1084,"u":1086,"pu":1083,"b":[["49999.6","2.500"]],"a":[["50000.4","1.940"]]}}
{"stream":"btcusdt@aggTrade","data":{"e":"aggTrade","E":1700000002200,"s":"BTCUSDT","a":9000014,"p":"49999.9","q":"0.036","f":18000028,"l":18000029,"T":1700000002180,"m":true}}
{"stream":"btcusdt@depth","data":{"e":"depthUpdate","E":1700000002250,"T":1700000002245,"s":"BTCUSDT","U":1087,"u":1089,"pu":1086,"b":[["49999.5","2.550"]],"a":[["50000.5","1.980"]]}}
{"stream":"btcusdt@depth","data":{"e":"depthUpdate","E":1700000002300,"T":1700000002295,"s":"BTCUSDT","U":1090,"u":1092,"pu":1089,"b":[["49999.4","2.600"],["49998.7","2.840"]],"a":[["50000.6","2.020"],["50001.3","2.260"]]}}
{"stream":"btcusdt@aggTrade","data":{"e":"aggTrade","E":1700000002350,"s":"BTCUSDT","a":9000015,"p":"50000.1","q":"0.038","f":18000030,"l":18000031,"T":1700000002330,"m":false}}
{"stream":"btcusdt@depth","data":{"e":"depthUpdate","E":1700000002400,"T":1700000002395,"s":"BTCUSDT","U":1093,"u":1095,"pu":1092,"b":[["49999.3","2.650"]],"a":[["50000.7","2.060"]]}}
{"stream":"btcusdt@forceOrder","data":{"e":"forceOrder","E":1700000002450,"o":{"s":"BTCUSDT","S":"BUY","o":"LIMIT","f":"IOC","q":"2.500","p":"50120.0","ap":"50115.5","X":"FILLED","l":"2.500","z":"2.500","T":1700000002440}}}
{"stream":"btcusdt@depth","data":{"e":"depthUpdate","E":1700000002500,"T":1700000002495,"s":"BTCUSDT","U":1096,"u":1098,"pu":1095,"b":[["49999.8","2.700"]],"a":[["50000.2","2.100"]]}}
{"stream":"btcusdt@aggTrade","data":{"e":"aggTrade","E":1700000002550,"s":"BTCUSDT","a":9000016,"p":"49999.9","q":"0.040","f":18000032,"l":18000033,"T":1700000002530,"m":true}}
{"stream":"btcusdt@depth","data":{"e":"depthUpdate","E":1700000002600,"T":1700000002595,"s":"BTCUSDT","U":1099,"u":1101,"pu":1098,"b":[["49999.7","2.750"]],"a":[["50000.3","2.140"]]}}
{"stream":"btcusdt@depth","data":{"e":"depthUpdate","E":1700000002650,"T":1700000002645,"s":"BTCUSDT","U":1102,"u":1104,"pu":1101,"b":[["49999.6","2.800"],["49998.7","2.960"]],"a":[["50000.4","2.180"],["50001.3","2.340"]]}}
{"stream":"btcusdt@aggTrade","data":{"e":"aggTrade","E":1700000002700,"s":"BTCUSDT","a":9000017,"p":"50000.1","q":"0.042","f":18000034,"l":18000035,"T":1700000002680,"m":false}}
{"stream":"btcusdt@depth","data":{"e":"depthUpdate","E":1700000002750,"T":1700000002745,"s":"BTCUSDT","U":1105,"u":1107,"pu":1104,"b":[["49999.5","2.850"]],"a":[["50000.5","2.220"]]}}
{"stream":"btcusdt@depth","data":{"e":"depthUpdate","E":1700000002800,"T":1700000002795,"s":"BTCUSDT","U":1108,"u":1110,"pu":1107,"b":[["49999.4","2.900"]],"a":[["50000.6","2.260"]]}}
{"stream":"btcusdt@aggTrade","data":{"e":"aggTrade","E":1700000002850,"s":"BTCUSDT","a":9000018,"p":"49999.9","q":"0.044","f":18000036,"l":18000037,"T":1700000002830,"m":true}}
{"stream":"btcusdt@bookTicker","data":{"e":"bookTicker","u":500034,"E":1700000002900,"T":1700000002897,"s":"BTCUSDT","b":"49999.9","B":"1.840","a":"50000.1","A":"1.200"}}
{"stream":"btcusdt@depth","data":{"e":"depthUpdate","E":1700000002950,"T":1700000002945,"s":"BTCUSDT","U":1111,"u":1113,"pu":1110,"b":[["49999.3","2.950"]],"a":[["50000.7","2.300"]]}}
{"stream":"btcusdt@depth","data":{"e":"depthUpdate","E":1700000003000,"T":1700000002995,"s":"BTCUSDT","U":1114,"u":1116,"pu":1113,"b":[["49999.8","3.000"],["49998.7","3.080"]],"a":[["50000.2","2.340"],["50001.3","2.420"]]}}
{"stream":"btcusdt@aggTrade","data":{"e":"aggTrade","E":1700000003050,"s":"BTCUSDT","a":9000019,"p":"50000.1","q":"0.046","f":18000038,"l":18000039,"T":1700000003030,"m":false}}
{"stream":"btcusdt@depth","data":{"e":"depthUpdate","E":1700000003100,"T":1700000003095,"s":"BTCUSDT","U":1117,"u":1119,"pu":1116,"b":[["49999.7","3.050"]],"a":[["50000.3","2.380"]]}}
{"stream":"btcusdt@depth","data":{"e":"depthUpdate","E":1700000003150,"T":1700000003145,"s":"BTCUSDT","U":1120,"u":1122,"pu":1119,"b":[["49999.6","3.100"]],"a":[["50000.4","2.420"]]}}
{"stream":"btcusdt@aggTrade","data":{"e":"aggTrade","E":1700000003200,"s":"BTCUSDT","a":9000020,"p":"49999.9","q":"0.048","f":18000040,"l":18000041,"T":1700000003180,"m":true}}
{"stream":"btcusdt@depth","data":{"e":"depthUpdate","E":1700000003250,"T":1700000003245,"s":"BTCUSDT","U":1123,"u":1125,"pu":1122,"b":[["49997.7","7.777"]],"a":[["50000.5","2.460"]]}}
{"stream":"btcusdt@depth","data":{"e":"depthUpdate","E":1700000003300,"T":1700000003295,"s":"BTCUSDT","U":1126,"u":1128,"pu":1125,"b":[["49999.4","3.200"],["49998.7","3.200"]],"a":[["50000.6","2.500"],["50001.3","2.500"]]}}
{"stream":"btcusdt@aggTrade","data":{"e":"aggTrade","E":1700000003350,"s":"BTCUSDT","a":9000021,"p":"50000.1","q":"0.050","f":18000042,"l":18000043,"T":1700000003330,"m":false}}
{"stream":"btcusdt@depth","data":{"e":"depthUpdate","E":1700000003400,"T":1700000003395,"s":"BTCUSDT","U":1129,"u":1131,"pu":1128,"b":[["49999.3","3.250"]],"a":[["50000.7","2.540"]]}}
{"stream":"btcusdt@depth","data":{"e":"depthUpdate","E":1700000003450,"T":1700000003445,"s":"BTCUSDT","U":1132,"u":1134,"pu":1131,"b":[["49999.8","3.300"]],"a":[["50000.2","2.580"]]}}
{"stream":"btcusdt@aggTrade","data":{"e":"aggTrade","E":1700000003500,"s":"BTCUSDT","a":9000022,"p":"49999.9","q":"0.052","f":18000044,"l":18000045,"T":1700000003480,"m":true}}
{"stream":"btcusdt@depth","data":{"e":"depthUpdate","E":1700000003550,"T":1700000003545,"s":"BTCUSDT","U":1135,"u":1137,"pu":1134,"b":[["49999.7","3.350"]],"a":[["50000.3","2.620"]]}}
{"stream":"btcusdt@depth","data":{"e":"depthUpdate","E":1700000003600,"T":1700000003595,"s":"BTCUSDT","U":1138,"u":1140,"pu":1137,"b":[["49999.6","3.400"],["49998.7","3.320"]],"a":[["50000.4","2.660"],["50001.3","2.580"]]}}
{"stream":"btcusdt@aggTrade","data":{"e":"aggTrade","E":1700000003650,"s":"BTCUSDT","a":9000023,"p":"50000.1","q":"0.054","f":18000046,"l":18000047,"T":1700000003630,"m":false}}
{"stream":"btcusdt@depth","data":{"e":"depthUpdate","E":1700000003700,"T":1700000003695,"s":"BTCUSDT","U":1141,"u":1143,"pu":1140,"b":[["49999.5","3.450"]],"a":[["50000.5","2.700"]]}}
{"stream":"btcusdt@depth","data":{"e":"depthUpdate","E":1700000003750,"T":1700000003745,"s":"BTCUSDT","U":1144,"u":1146,"pu":1143,"b":[["49999.4","3.500"]],"a":[["50000.6","2.740"]]}}
{"stream":"btcusdt@aggTrade","data":{"e":"aggTrade","E":1700000003800,"s":"BTCUSDT","a":9000024,"p":"49999.9","q":"0.056","f":18000048,"l":18000049,"T":1700000003780,"m":true}}
{"stream":"btcusdt@depth","data":{"e":"depthUpdate","E":1700000003850,"T":1700000003845,"s":"BTCUSDT","U":1147,"u":1149,"pu":1146,"b":[["49999.3","3.550"]],"a":[["50000.7","2.780"]]}}
{"stream":"btcusdt@depth","data":{"e":"depthUpdate","E":1700000003900,"T":1700000003895,"s":"BTCUSDT","U":1150,"u":1152,"pu":1149,"b":[["49999.8","3.600"],["49998.7","3.440"]],"a":[["50000.2","2.820"],["50001.3","2.660"]]}}
{"stream":"btcusdt@aggTrade","data":{"e":"aggTrade","E":1700000003950,"s":"BTCUSDT","a":9000025,"p":"50000.1","q":"0.058","f":18000050,"l":18000051,"T":1700000003930,"m":false}}
{"stream":"btcusdt@depth","data":{"e":"depthUpdate","E":1700000004000,"T":1700000003995,"s":"BTCUSDT","U":1153,"u":1155,"pu":1152,"b":[["49999.7","3.650"]],"a":[["50000.3","2.860"]]}}
{"stream":"btcusdt@depth","data":{"e":"depthUpdate","E":1700000004050,"T":1700000004045,"s":"BTCUSDT","U":1156,"u":1158,"pu":1155,"b":[["49999.6","3.700"]],"a":[["50000.4","2.900"]]}}
{"stream":"btcusdt@aggTrade","data":{"e":"aggTrade","E":1700000004100,"s":"BTCUSDT","a":9000026,"p":"49999.9","q":"0.060","f":18000052,"l":18000053,"T":1700000004080,"m":true}}
{"stream":"btcusdt@depth","data":{"e":"depthUpdate","E":1700000004150,"T":1700000004145,"s":"BTCUSDT","U":1159,"u":1161,"pu":1158,"b":[["49999.5","3.750"]],"a":[["50000.5","2.940"]]}}
{"stream":"btcusdt@depth","data":{"e":"depthUpdate","E":1700000004200,"T":1700000004195,"s":"BTCUSDT","U":1162,"u":1164,"pu":1161,"b":[["49999.4","3.800"],["49998.7","3.560"]],"a":[["50000.6","2.980"],["50001.3","2.740"]]}}
{"stream":"btcusdt@aggTrade","data":{"e":"aggTrade","E":1700000004250,"s":"BTCUSDT","a":9000027,"p":"50000.1","q":"0.062","f":18000054,"l":18000055,"T":1700000004230,"m":false}}
{"stream":"btcusdt@depth","data":{"e":"depthUpdate","E":1700000004300,"T":1700000004295,"s":"BTCUSDT","U":1165,"u":1167,"pu":1164,"b":[["49999.3","3.850"]],"a":[["50000.7","3.020"]]}}
{"stream":"btcusdt@depth","data":{"e":"depthUpdate","E":1700000004350,"T":1700000004345,"s":"BTCUSDT","U":1168,"u":1170,"pu":1167,"b":[["49999.8","3.900"]],"a":[["50000.2","3.060"]]}}
{"stream":"btcusdt@aggTrade","data":{"e":"aggTrade","E":1700000004400,"s":"BTCUSDT","a":9000028,"p":"49999.9","q":"0.064","f":18000056,"l":18000057,"T":1700000004380,"m":true}}
{"stream":"btcusdt@bookTicker","data":{"e":"bookTicker","u":500051,"E":1700000004450,"T":1700000004447,"s":"BTCUSDT","b":"49999.9","B":"2.040","a":"50000.1","A":"1.200"}}
{"stream":"btcusdt@depth","data":{"e":"depthUpdate","E":1700000004500,"T":1700000004495,"s":"BTCUSDT","U":1171,"u":1173,"pu":1170,"b":[["49999.7","3.950"]],"a":[["50000.3","3.100"]]}}
{"stream":"btcusdt@depth","data":{"e":"depthUpdate","E":1700000004550,"T":1700000004545,"s":"BTCUSDT","U":1174,"u":1176,"pu":1173,"b":[["49999.6","4.000"],["49998.7","3.680"]],"a":[["50000.4","3.140"],["50001.3","2.820"]]}}
{"stream":"btcusdt@aggTrade","data":{"e":"aggTrade","E":1700000004600,"s":"BTCUSDT","a":9000029,"p":"50000.1","q":"0.066","f":18000058,"l":18000059,"T":1700000004580,"m":false}}
{"stream":"btcusdt@depth","data":{"e":"depthUpdate","E":1700000004650,"T":1700000004645,"s":"BTCUSDT","U":1177,"u":1179,"pu":1176,"b":[["49999.5","4.050"]],"a":[["50000.5","3.180"]]}}
{"stream":"btcusdt@depth","data":{"e":"depthUpdate","E":1700000004700,"T":1700000004695,"s":"BTCUSDT","U":1180,"u":1182,"pu":1179,"b":[["49999.4","4.100"]],"a":[["50000.6","3.220"]]}}
{"stream":"btcusdt@aggTrade","data":{"e":"aggTrade","E":1700000004750,"s":"BTCUSDT","a":9000030,"p":"49999.9","q":"0.068","f":18000060,"l":18000061,"T":1700000004730,"m":true}}
{"stream":"btcusdt@depth","data":{"e":"depthUpdate","E":1700000004800,"T":1700000004795,"s":"BTCUSDT","U":2095,"u":2100,"pu":1500,"b":[["50009.9","2.000"]],"a":[["50010.3","1.500"]]}}
{"rest_depth_snapshot":{"lastUpdateId":2050,"E":1700000004810,"T":1700000004805,"bids":[["50009.9","1.400"],["50009.8","1.510"],["50009.7","1.620"],["50009.6","1.730"],["50009.5","1.840"],["50009.4","1.400"],["50009.3","1.510"],["50009.2","1.620"],["50009.1","1.730"],["50009.0","1.840"],["50008.9","1.400"],["50008.8","1.510"],["50008.7","1.620"],["50008.6","1.730"],["50008.5","1.840"],["50008.4","1.400"],["50008.3","1.510"],["50008.2","1.620"],["50008.1","1.730"],["50008.0","1.840"]],"asks":[["50010.1","1.100"],["50010.2","1.190"],["50010.3","1.280"],["50010.4","1.370"],["50010.5","1.100"],["50010.6","1.190"],["50010.7","1.280"],["50010.8","1.370"],["50010.9","1.100"],["50011.0","1.190"],["50011.1","1.280"],["50011.2","1.370"],["50011.3","1.100"],["50011.4","1.190"],["50011.5","1.280"],["50011.6","1.370"],["50011.7","1.100"],["50011.8","1.190"],["50011.9","1.280"],["50012.0","1.370"]]}}
{"stream":"btcusdt@depth","data":{"e":"depthUpdate","E":1700000004850,"T":1700000004845,"s":"BTCUSDT","U":2101,"u":2103,"pu":2100,"b":[["50009.8","1.300"]],"a":[["50010.2","1.000"]]}}
{"stream":"btcusdt@depth","data":{"e":"depthUpdate","E":1700000004900,"T":1700000004895,"s":"BTCUSDT","U":2104,"u":2106,"pu":2103,"b":[["50009.7","1.350"]],"a":[["50010.3","1.030"]]}}
{"stream":"btcusdt@aggTrade","data":{"e":"aggTrade","E":1700000004950,"s":"BTCUSDT","a":9000031,"p":"50010.1","q":"0.021","f":18000062,"l":18000063,"T":1700000004930,"m":false}}
{"stream":"btcusdt@depth","data":{"e":"depthUpdate","E":1700000005000,"T":1700000004995,"s":"BTCUSDT","U":2107,"u":2109,"pu":2106,"b":[["50009.6","1.400"]],"a":[["50010.4","1.060"]]}}
{"stream":"btcusdt@depth","data":{"e":"depthUpdate","E":1700000005050,"T":1700000005045,"s":"BTCUSDT","U":2110,"u":2112,"pu":2109,"b":[["50009.5","1.450"]],"a":[["50010.5","1.090"]]}}
{"stream":"btcusdt@aggTrade","data":{"e":"aggTrade","E":1700000005100,"s":"BTCUSDT","a":9000032,"p":"50009.9","q":"0.023","f":18000064,"l":18000065,"T":1700000005080,"m":true}}
{"stream":"btcusdt@depth","data":{"e":"depthUpdate","E":1700000005150,"T":1700000005145,"s":"BTCUSDT","U":2113,"u":2115,"pu":2112,"b":[["50009.4","1.500"]],"a":[["50010.6","1.120"]]}}
{"stream":"btcusdt@depth","data":{"e":"depthUpdate","E":1700000005200,"T":1700000005195,"s":"BTCUSDT","U":2116,"u":2118,"pu":2115,"b":[["50009.3","1.550"]],"a":[["50010.7","1.150"]]}}
{"stream":"btcusdt@aggTrade","data":{"e":"aggTrade","E":1700000005250,"s":"BTCUSDT","a":9000033,"p":"50010.1","q":"0.025","f":18000066,"l":18000067,"T":1700000005230,"m":false}}
{"stream":"btcusdt@depth","data":{"e":"depthUpdate","E":1700000005300,"T":1700000005295,"s":"BTCUSDT","U":2119,"u":2121,"pu":2118,"b":[["50009.8","1.600"]],"a":[["50010.2","1.180"]]}}
{"stream":"btcusdt@depth","data":{"e":"depthUpdate","E":1700000005350,"T":1700000005345,"s":"BTCUSDT","U":2122,"u":2124,"pu":2121,"b":[["50009.7","1.650"]],"a":[["50010.3","1.210"]]}}
{"stream":"btcusdt@aggTrade","data":{"e":"aggTrade","E":1700000005400,"s":"BTCUSDT","a":9000034,"p":"50009.9","q":"0.027","f":18000068,"l":18000069,"T":1700000005380,"m":true}}
{"stream":"btcusdt@depth","data":{"e":"depthUpdate","E":1700000005450,"T":1700000005445,"s":"BTCUSDT","U":2125,"u":2127,"pu":2124,"b":[["50009.6","1.700"]],"a":[["50010.4","1.240"]]}}
{"stream":"btcusdt@depth","data":{"e":"depthUpdate","E":1700000005500,"T":1700000005495,"s":"BTCUSDT","U":2128,"u":2130,"pu":2127,"b":[["50009.5","1.750"]],"a":[["50010.5","1.270"]]}}
{"stream":"btcusdt@aggTrade","data":{"e":"aggTrade","E":1700000005550,"s":"BTCUSDT","a":9000035,"p":"50010.1","q":"0.029","f":18000070,"l":18000071,"T":1700000005530,"m":false}}
{"stream":"btcusdt@depth","data":{"e":"depthUpdate","E":1700000005600,"T":1700000005595,"s":"BTCUSDT","U":2131,"u":2133,"pu":2130,"b":[["50009.4","1.800"]],"a":[["50010.6","1.300"]]}}
{"stream":"btcusdt@depth","data":{"e":"depthUpdate","E":1700000005650,"T":1700000005645,"s":"BTCUSDT","U":2134,"u":2136,"pu":2133,"b":[["50009.3","1.850"]],"a":[["50010.7","1.330"]]}}
{"stream":"btcusdt@aggTrade","data":{"e":"aggTrade","E":1700000005700,"s":"BTCUSDT","a":9000036,"p":"50009.9","q":"0.031","f":18000072,"l":18000073,"T":1700000005680,"m":true}}
{"stream":"btcusdt@depth","data":{"e":"depthUpdate","E":1700000005750,"T":1700000005745,"s":"BTCUSDT","U":2137,"u":2139,"pu":2136,"b":[["50009.8","1.900"]],"a":[["50010.2","1.360"]]}}
{"stream":"btcusdt@depth","data":{"e":"depthUpdate","E":1700000005800,"T":1700000005795,"s":"BTCUSDT","U":2140,"u":2142,"pu":2139,"b":[["50009.7","1.950"]],"a":[["50010.3","1.390"]]}}
{"stream":"btcusdt@aggTrade","data":{"e":"aggTrade","E":1700000005850,"s":"BTCUSDT","a":9000037,"p":"50010.1","q":"0.033","f":18000074,"l":18000075,"T":1700000005830,"m":false}}
{"stream":"btcusdt@depth","data":{"e":"depthUpdate","E":1700000005900,"T":1700000005895,"s":"BTCUSDT","U":2143,"u":2145,"pu":2142,"b":[["50009.6","2.000"]],"a":[["50010.4","1.420"]]}}
{"stream":"btcusdt@depth","data":{"e":"depthUpdate","E":1700000005950,"T":1700000005945,"s":"BTCUSDT","U":2146,"u":2148,"pu":2145,"b":[["50009.5","2.050"]],"a":[["50010.5","1.450"]]}}
{"stream":"btcusdt@aggTrade","data":{"e":"aggTrade","E":1700000006000,"s":"BTCUSDT","a":9000038,"p":"50009.9","q":"0.035","f":18000076,"l":18000077,"T":1700000005980,"m":true}}
{"stream":"btcusdt@depth","data":{"e":"depthUpdate","E":1700000006050,"T":1700000006045,"s":"BTCUSDT","U":2149,"u":2151,"pu":2148,"b":[["50009.4","2.100"]],"a":[["50010.6","1.480"]]}}
{"stream":"btcusdt@depth","data":{"e":"depthUpdate","E":1700000006100,"T":1700000006095,"s":"BTCUSDT","U":2152,"u":2154,"pu":2151,"b":[["50009.3","2.150"]],"a":[["50010.7","1.510"]]}}
{"stream":"btcusdt@aggTrade","data":{"e":"aggTrade","E":1700000006150,"s":"BTCUSDT","a":9000039,"p":"50010.1","q":"0.037","f":18000078,"l":18000079,"T":1700000006130,"m":false}}
{"stream":"btcusdt@depth","data":{"e":"depthUpdate","E":1700000006200,"T":1700000006195,"s":"BTCUSDT","U":2155,"u":2157,"pu":2154,"b":[["50009.8","2.200"]],"a":[["50010.2","1.540"]]}}
{"stream":"btcusdt@depth","data":{"e":"depthUpdate","E":1700000006250,"T":1700000006245,"s":"BTCUSDT","U":2158,"u":2160,"pu":2157,"b":[["50009.7","2.250"]],"a":[["50010.3","1.570"]]}}
{"stream":"btcusdt@aggTrade","data":{"e":"aggTrade","E":1700000006300,"s":"BTCUSDT","a":9000040,"p":"50009.9","q":"0.039","f":18000080,"l":18000081,"T":1700000006280,"m":true}}
{"stream":"btcusdt@bookTicker","data":{"e":"bookTicker","u":500068,"E":1700000006350,"T":1700000006347,"s":"BTCUSDT","b":"50009.9","B":"2.000","a":"50010.1","A":"1.990"}}
{"stream":"btcusdt@depth","data":{"e":"depthUpdate","E":1700000006400,"T":1700000006395,"s":"BTCUSDT","U":2161,"u":2163,"pu":2160,"b":[["50009.6","2.300"]],"a":[["50010.4","1.600"]]}}
{"stream":"btcusdt@depth","data":{"e":"depthUpdate","E":1700000006450,"T":1700000006445,"s":"BTCUSDT","U":2164,"u":2166,"pu":2163,"b":[["50009.5","2.350"]],"a":[["50010.5","1.630"]]}}
{"stream":"btcusdt@aggTrade","data":{"e":"aggTrade","E":1700000006500,"s":"BTCUSDT","a":9000041,"p":"50010.1","q":"0.041","f":18000082,"l":18000083,"T":1700000006480,"m":false}}
{"stream":"btcusdt@depth","data":{"e":"depthUpdate","E":1700000006550,"T":1700000006545,"s":"BTCUSDT","U":2167,"u":2169,"pu":2166,"b":[["50009.4","2.400"]],"a":[["50010.6","1.660"]]}}
{"stream":"btcusdt@depth","data":{"e":"depthUpdate","E":1700000006600,"T":1700000006595,"s":"BTCUSDT","U":2170,"u":2172,"pu":2169,"b":[["50009.3","2.450"]],"a":[["50010.7","1.690"]]}}
{"stream":"btcusdt@aggTrade","data":{"e":"aggTrade","E":1700000006650,"s":"BTCUSDT","a":9000042,"p":"50009.9","q":"0.043","f":18000084,"l":18000085,"T":1700000006630,"m":true}}
{"stream":"btcusdt@depth","data":{"e":"depthUpdate","E":1700000006700,"T":1700000006695,"s":"BTCUSDT","U":2173,"u":2175,"pu":2172,"b":[["50007.3","4.444"]],"a":[["50010.2","1.720"]]}}
{"stream":"btcusdt@depth","data":{"e":"depthUpdate","E":1700000006750,"T":1700000006745,"s":"BTCUSDT","U":2176,"u":2178,"pu":2175,"b":[["50009.7","2.550"]],"a":[["50010.3","1.750"]]}}
{"stream":"btcusdt@aggTrade","data":{"e":"aggTrade","E":1700000006800,"s":"BTCUSDT","a":9000043,"p":"50010.1","q":"0.045","f":18000086,"l":18000087,"T":1700000006780,"m":false}}
{"stream":"btcusdt@depth","data":{"e":"depthUpdate","E":1700000006850,"T":1700000006845,"s":"BTCUSDT","U":2179,"u":2181,"pu":2178,"b":[["50009.6","2.600"]],"a":[["50010.4","1.780"]]}}
{"stream":"btcusdt@depth","data":{"e":"depthUpdate","E":1700000006900,"T":1700000006895,"s":"BTCUSDT","U":2182,"u":2184,"pu":2181,"b":[["50009.5","2.650"]],"a":[["50010.5","1.810"]]}}
{"stream":"btcusdt@aggTrade","data":{"e":"aggTrade","E":1700000006950,"s":"BTCUSDT","a":9000044,"p":"50009.9","q":"0.047","f":18000088,"l":18000089,"T":1700000006930,"m":true}}
{"stream":"btcusdt@depth","data":{"e":"depthUpdate","E":1700000007000,"T":1700000006995,"s":"BTCUSDT","U":2185,"u":2187,"pu":2184,"b":[["50009.4","2.700"]],"a":[["50010.6","1.840"]]}}
{"stream":"btcusdt@depth","data":{"e":"depthUpdate","E":1700000007050,"T":1700000007045,"s":"BTCUSDT","U":2188,"u":2190,"pu":2187,"b":[["50009.3","2.750"]],"a":[["50010.7","1.870"]]}}
{"stream":"btcusdt@aggTrade","data":{"e":"aggTrade","E":1700000007100,"s":"BTCUSDT","a":9000045,"p":"50010.1","q":"0.049","f":18000090,"l":18000091,"T":1700000007080,"m":false}}
{"stream":"btcusdt@depth","data":{"e":"depthUpdate","E":1700000007150,"T":1700000007145,"s":"BTCUSDT","U":2191,"u":2193,"pu":2190,"b":[["50009.8","2.800"]],"a":[["50010.2","1.900"]]}}
{"stream":"btcusdt@depth","data":{"e":"depthUpdate","E":1700000007200,"T":1700000007195,"s":"BTCUSDT","U":2194,"u":2196,"pu":2193,"b":[["50009.7","2.850"]],"a":[["50010.3","1.930"]]}}
{"stream":"btcusdt@aggTrade","data":{"e":"aggTrade","E":1700000007250,"s":"BTCUSDT","a":9000046,"p":"50009.9","q":"0.051","f":18000092,"l":18000093,"T":1700000007230,"m":true}}
{"stream":"btcusdt@depth","data":{"e":"depthUpdate","E":1700000007300,"T":1700000007295,"s":"BTCUSDT","U":2197,"u":2199,"pu":2196,"b":[["50009.6","2.900"]],"a":[["50010.4","1.960"]]}}
{"stream":"btcusdt@depth","data":{"e":"depthUpdate","E":1700000007350,"T":1700000007345,"s":"BTCUSDT","U":2200,"u":2202,"pu":2199,"b":[["50009.5","2.950"]],"a":[["50010.5","1.990"]]}}
{"stream":"btcusdt@aggTrade","data":{"e":"aggTrade","E":1700000007400,"s":"BTCUSDT","a":9000047,"p":"50010.1","q":"0.053","f":18000094,"l":18000095,"T":1700000007380,"m":false}}
{"stream":"btcusdt@depth","data":{"e":"depthUpdate","E":1700000007450,"T":1700000007445,"s":"BTCUSDT","U":2203,"u":2205,"pu":2202,"b":[["50009.4","3.000"]],"a":[["50010.6","2.020"]]}}
{"stream":"btcusdt@depth","data":{"e":"depthUpdate","E":1700000007500,"T":1700000007495,"s":"BTCUSDT","U":2206,"u":2208,"pu":2205,"b":[["50009.3","3.050"]],"a":[["50010.7","2.050"]]}}
{"stream":"btcusdt@aggTrade","data":{"e":"aggTrade","E":1700000007550,"s":"BTCUSDT","a":9000048,"p":"50009.9","q":"0.055","f":18000096,"l":18000097,"T":1700000007530,"m":true}}
{"stream":"btcusdt@depth","data":{"e":"depthUpdate","E":1700000007600,"T":1700000007595,"s":"BTCUSDT","U":2209,"u":2211,"pu":2208,"b":[["50009.8","3.100"]],"a":[["50010.2","2.080"]]}}
{"stream":"btcusdt@depth","data":{"e":"depthUpdate","E":1700000007650,"T":1700000007645,"s":"BTCUSDT","U":2212,"u":2214,"pu":2211,"b":[["50009.7","3.150"]],"a":[["50010.3","2.110"]]}}
{"stream":"btcusdt@aggTrade","data":{"e":"aggTrade","E":1700000007700,"s":"BTCUSDT","a":9000049,"p":"50010.1","q":"0.057","f":18000098,"l":18000099,"T":1700000007680,"m":false}}
{"stream":"btcusdt@depth","data":{"e":"depthUpdate","E":1700000007750,"T":1700000007745,"s":"BTCUSDT","U":2215,"u":2217,"pu":2214,"b":[["50009.6","3.200"]],"a":[["50010.4","2.140"]]}}
{"stream":"btcusdt@depth","data":{"e":"depthUpdate","E":1700000007800,"T":1700000007795,"s":"BTCUSDT","U":2218,"u":2220,"pu":2217,"b":[["50009.5","3.250"]],"a":[["50010.5","2.170"]]}}
{"stream":"btcusdt@aggTrade","data":{"e":"aggTrade","E":1700000007850,"s":"BTCUSDT","a":9000050,"p":"50009.9","q":"0.059","f":18000100,"l":18000101,"T":1700000007830,"m":true}}
{"stream":"btcusdt@depth","data":{"e":"depthUpdate","E":1700000007900,"T":1700000007895,"s":"BTCUSDT","U":2221,"u":2223,"pu":2220,"b":[["50009.4","3.300"]],"a":[["50010.6","2.200"]]}}
{"stream":"btcusdt@depth","data":{"e":"depthUpdate","E":1700000007950,"T":1700000007945,"s":"BTCUSDT","U":2224,"u":2226,"pu":2223,"b":[["50009.3","3.350"]],"a":[["50010.7","2.230"]]}}
{"stream":"btcusdt@aggTrade","data":{"e":"aggTrade","E":1700000008000,"s":"BTCUSDT","a":9000051,"p":"50010.1","q":"0.061","f":18000102,"l":18000103,"T":1700000007980,"m":false}}
{"stream":"btcusdt@depth","data":{"e":"depthUpdate","E":1700000008050,"T":1700000008045,"s":"BTCUSDT","U":2227,"u":2229,"pu":2226,"b":[["50009.8","3.400"]],"a":[["50010.2","2.260"]]}}
{"stream":"btcusdt@depth","data":{"e":"depthUpdate","E":1700000008100,"T":1700000008095,"s":"BTCUSDT","U":2230,"u":2232,"pu":2229,"b":[["50009.7","3.450"]],"a":[["50010.3","2.290"]]}}
{"stream":"btcusdt@aggTrade","data":{"e":"aggTrade","E":1700000008150,"s":"BTCUSDT","a":9000052,"p":"50009.9","q":"0.063","f":18000104,"l":18000105,"T":1700000008130,"m":true}}
{"stream":"btcusdt@depth","data":{"e":"depthUpdate","E":1700000008200,"T":1700000008195,"s":"BTCUSDT","U":2233,"u":2235,"pu":2232,"b":[["50009.6","3.500"]],"a":[["50010.4","2.320"]]}}
{"stream":"btcusdt@bookTicker","data":{"e":"bookTicker","u":500085,"E":1700000008250,"T":1700000008247,"s":"BTCUSDT","b":"50009.9","B":"2.000","a":"50010.1","A":"2.240"}}
{"stream":"btcusdt@depth","data":{"e":"depthUpdate","E":1700000008300,"T":1700000008295,"s":"BTCUSDT","U":2236,"u":2238,"pu":2235,"b":[["50009.5","3.550"]],"a":[["50010.5","2.350"]]}}
{"stream":"btcusdt@aggTrade","data":{"e":"aggTrade","E":1700000008350,"s":"BTCUSDT","a":9000053,"p":"50010.1","q":"0.065","f":18000106,"l":18000107,"T":1700000008330,"m":false}}
{"stream":"btcusdt@depth","data":{"e":"depthUpdate","E":1700000008400,"T":1700000008395,"s":"BTCUSDT","U":2239,"u":2241,"pu":2238,"b":[["50009.4","3.600"]],"a":[["50010.6","2.380"]]}}
{"stream":"btcusdt@depth","data":{"e":"depthUpdate","E":1700000008450,"T":1700000008445,"s":"BTCUSDT","U":2242,"u":2244,"pu":2241,"b":[["50009.3","3.650"]],"a":[["50010.7","2.410"]]}}
{"stream":"btcusdt@aggTrade","data":{"e":"aggTrade","E":1700000008500,"s":"BTCUSDT","a":9000054,"p":"50009.9","q":"0.067","f":18000108,"l":18000109,"T":1700000008480,"m":true}}
{"stream":"btcusdt@depth","data":{"e":"depthUpdate","E":1700000008550,"T":1700000008545,"s":"BTCUSDT","U":2245,"u":2247,"pu":2244,"b":[["50009.8","3.700"]],"a":[["50010.2","2.440"]]}}
{"stream":"btcusdt@depth","data":{"e":"depthUpdate","E":1700000008600,"T":1700000008595,"s":"BTCUSDT","U":2248,"u":2250,"pu":2247,"b":[["50009.7","3.750"]],"a":[["50010.3","2.470"]]}}
{"stream":"btcusdt@aggTrade","data":{"e":"aggTrade","E":1700000008650,"s":"BTCUSDT","a":9000055,"p":"50010.1","q":"0.069","f":18000110,"l":18000111,"T":1700000008630,"m":false}}
{"stream":"btcusdt@depth","data":{"e":"depthUpdate","E":1700000008700,"T":1700000008695,"s":"BTCUSDT","U":2251,"u":2253,"pu":2250,"b":[["50009.6","3.800"]],"a":[["50010.4","2.500"]]}}
{"stream":"btcusdt@depth","data":{"e":"depthUpdate","E":1700000008750,"T":1700000008745,"s":"BTCUSDT","U":2254,"u":2256,"pu":2253,"b":[["50009.5","3.850"]],"a":[["50010.5","2.530"]]}}
{"stream":"btcusdt@aggTrade","data":{"e":"aggTrade","E":1700000008800,"s":"BTCUSDT","a":9000056,"p":"50009.9","q":"0.071","f":18000112,"l":18000113,"T":1700000008780,"m":true}}
{"stream":"btcusdt@depth","data":{"e":"depthUpdate","E":1700000008850,"T":1700000008845,"s":"BTCUSDT","U":2257,"u":2259,"pu":2256,"b":[["50009.4","3.900"]],"a":[["50010.6","2.560"]]}}
{"stream":"btcusdt@depth","data":{"e":"depthUpdate","E":1700000008900,"T":1700000008895,"s":"BTCUSDT","U":2260,"u":2262,"pu":2259,"b":[["50009.3","3.950"]],"a":[["50010.7","2.590"]]}}
{"stream":"btcusdt@aggTrade","data":{"e":"aggTrade","E":1700000008950,"s":"BTCUSDT","a":9000057,"p":"50010.1","q":"0.073","f":18000114,"l":18000115,"T":1700000008930,"m":false}}
{"stream":"btcusdt@depth","data":{"e":"depthUpdate","E":1700000009000,"T":1700000008995,"s":"BTCUSDT","U":2263,"u":2265,"pu":2262,"b":[["50009.8","4.000"]],"a":[["50010.2","2.620"]]}}
{"stream":"btcusdt@depth","data":{"e":"depthUpdate","E":1700000009050,"T":1700000009045,"s":"BTCUSDT","U":2266,"u":2268,"pu":2265,"b":[["50009.7","4.050"]],"a":[["50010.3","2.650"]]}}
{"stream":"btcusdt@aggTrade","data":{"e":"aggTrade","E":1700000009100,"s":"BTCUSDT","a":9000058,"p":"50009.9","q":"0.075","f":18000116,"l":18000117,"T":1700000009080,"m":true}}
{"stream":"btcusdt@depth","data":{"e":"depthUpdate","E":1700000009150,"T":1700000009145,"s":"BTCUSDT","U":2269,"u":2271,"pu":2268,"b":[["50009.6","4.100"]],"a":[["50010.4","2.680"]]}}
{"stream":"btcusdt@depth","data":{"e":"depthUpdate","E":1700000009200,"T":1700000009195,"s":"BTCUSDT","U":2272,"u":2274,"pu":2271,"b":[["50009.5","4.150"]],"a":[["50010.5","2.710"]]}}
{"stream":"btcusdt@aggTrade","data":{"e":"aggTrade","E":1700000009250,"s":"BTCUSDT","a":9000059,"p":"50010.1","q":"0.077","f":18000118,"l":18000119,"T":1700000009230,"m":false}}
{"stream":"btcusdt@depth","data":{"e":"depthUpdate","E":1700000009300,"T":1700000009295,"s":"BTCUSDT","U":2275,"u":2277,"pu":2274,"b":[["50009.4","4.200"]],"a":[["50010.6","2.740"]]}}
{"stream":"btcusdt@depth","data":{"e":"depthUpdate","E":1700000009350,"T":1700000009345,"s":"BTCUSDT","U":2278,"u":2280,"pu":2277,"b":[["50009.3","4.250"]],"a":[["50010.7","2.770"]]}}
{"stream":"btcusdt@aggTrade","data":{"e":"aggTrade","E":1700000009400,"s":"BTCUSDT","a":9000060,"p":"50009.9","q":"0.079","f":18000120,"l":18000121,"T":1700000009380,"m":true}}
{"stream":"btcusdt@depth","data":{"e":"depthUpdate","E":1700000009450,"T":1700000009445,"s":"BTCUSDT","U":2281,"u":2283,"pu":2280,"b":[["50009.8","4.300"]],"a":[["50010.2","2.800"]]}}
{"stream":"btcusdt@depth","data":{"e":"depthUpdate","E":1700000009500,"T":1700000009495,"s":"BTCUSDT","U":2284,"u":2286,"pu":2283,"b":[["50009.7","4.350"]],"a":[["50010.3","2.830"]]}}
{"stream":"btcusdt@depth","data":{"e":"depthUpdate","E":1700000009550,"T":1700000009545,"s":"BTCUSDT","U":2287,"u":2289,"pu":2286,"b":[["50009.6","4.400"]],"a":[["50010.4","2.860"]]}}
{"stream":"btcusdt@depth","data":{"e":"depthUpdate","E":1700000009600,"T":1700000009595,"s":"BTCUSDT","U":2290,"u":2292,"pu":2289,"b":[["50009.5","4.450"]],"a":[["50010.5","2.890"]]}}
{"stream":"btcusdt@depth","data":{"e":"depthUpdate","E":1700000009650,"T":1700000009645,"s":"BTCUSDT","U":2293,"u":2295,"pu":2292,"b":[["50009.4","4.500"]],"a":[["50010.6","2.920"]]}}
{"stream":"btcusdt@bookTicker","data":{"e":"bookTicker","u":500102,"E":1700000009700,"T":1700000009697,"s":"BTCUSDT","b":"50009.9","B":"2.000","a":"50010.1","A":"2.440"}}
{"stream":"btcusdt@depth","data":{"e":"depthUpdate","E":1700000009750,"T":1700000009745,"s":"BTCUSDT","U":2296,"u":2298,"pu":2295,"b":[["50009.3","4.550"]],"a":[["50010.7","2.950"]]}}
{"stream":"btcusdt@depth","data":{"e":"depthUpdate","E":1700000009800,"T":1700000009795,"s":"BTCUSDT","U":2299,"u":2301,"pu":2298,"b":[["50009.8","4.600"]],"a":[["50010.2","2.980"]]}}
{"stream":"btcusdt@depth","data":{"e":"depthUpdate","E":1700000009850,"T":1700000009845,"s":"BTCUSDT","U":2302,"u":2304,"pu":2301,"b":[["50009.7","4.650"]],"a":[["50010.3","3.010"]]}}
{"stream":"btcusdt@depth","data":{"e":"depthUpdate","E":1700000009900,"T":1700000009895,"s":"BTCUSDT","U":2305,"u":2307,"pu":2304,"b":[["50009.6","4.700"]],"a":[["50010.4","3.040"]]}}
{"stream":"btcusdt@depth","data":{"e":"depthUpdate","E":1700000009950,"T":1700000009945,"s":"BTCUSDT","U":2308,"u":2310,"pu":2307,"b":[["50009.5","4.750"]],"a":[["50010.5","3.070"]]}}
